<?xml version="1.0"?>
<robot name="pioneer2dx" xmlns:xacro="http://ros.org/wiki/xacro">
	<material name="chasis_gazebo">
		<color rgba="1 0 0 1" />
	</material>
	<material name="ruedas_gazebo">
		<color rgba="0 0 0 1" />
	</material>
	<link name="base_link" />
	<joint name="base_link_to_chassis" type="fixed">
		<parent link="base_link" />
		<child link="chassis" />
		<origin xyz="-0.1 0 0" rpy="0 0 0" />
		<!--<pose>-0.1 0 0 0 0 0</pose>-->
	</joint>
	<link name="chassis">
		<origin xyz="0 0 0.16" rpy="0 0 0" />
		<inertial>
			<mass value="10.0" />
			<inertia ixx="0.088" iyy="0.1965" izz="0.2365" ixz="0" ixy="0" iyz="0" /> <!-- Inertia of a cuboid, it depends on mass>-->
		</inertial>
		<collision name="chasis_collision">
			<geometry>
				<box size="0.445 0.277 0.17" />
			</geometry>
		</collision>
		<visual name="chasis_visual">
			<origin xyz="0 0 0.04" rpy="0 0 0" />
			<geometry>
				<mesh filename="package://pioneer2dx/meshes/chassis.dae" />
			</geometry>
		</visual>
	</link>


	<link name="castor">
		<inertial>
			<mass value="0.15" />
			<!--<inertia ixx="4.55e-3" iyy="7.5e-3" izz="4.55e-3" ixz="0.0" ixy="0.0" iyz="0.0" />-->
			<inertia ixx="4.55e-4" izz="4.55e-4" iyy="7.5e-4" ixz="0.0" ixy="0.0" iyz="0.0" />
		</inertial>
		<collision name="castor_collision">
			<origin xyz="0 0 0" rpy="1.57 0 0" />
			<geometry>
				<!--<mesh filename="package://pioneer2dx/meshes/wheel_v5.dae" scale="0.3 0.3 0.3" />--> <!--21.6cm de diametro por 8cm de ancho perfil esferico -->			
				<cylinder length="0.026" radius="0.036" />
			</geometry>
			<surface>
				<friction>
					<ode>
						<mu>1.0</mu>
						<mu2>1.0</mu2>
						<slip1>0</slip1>
						<slip2>0</slip2>
						<maxVel>0.0</maxVel>
						<minDepth>0.001</minDepth>
					</ode>
				</friction>
			</surface>
		</collision>
		<visual name="castor_visual">
			<origin xyz="0 0 0" rpy="0 0 0" />
			<geometry>
				<mesh filename="package://pioneer2dx/meshes/wheel_v5.dae" scale="0.3 0.3 0.3" /> <!--21.6cm de diametro por 8cm de ancho perfil esferico -->
				<!--<cylinder length="0.026" radius="0.036" />-->
			</geometry>
		</visual>
	</link>
	<link name="plate_castor">
		<inertial>
			<mass value="0.01" />
			<!--<inertia ixx="4.55e-3" iyy="7.5e-3" izz="4.55e-3" ixz="0.0" ixy="0.0" iyz="0.0" />-->
			<inertia ixx="4.55e-5" izz="4.55e-5" iyy="4.55e-5" ixz="0.0" ixy="0.0" iyz="0.0" />
		</inertial>
		<collision name="castor_plate_collision">
			<origin xyz="0 0 0" rpy="0 0 0" />
			<geometry>
				<cylinder length="0.01" radius="0.01" />
			</geometry>
		</collision>
		<visual name="castor_plate_visual">
			<origin xyz="0 0 0" rpy="0 0 0" />
			<geometry>
				<cylinder length="0.01" radius="0.01" />
			</geometry>
		</visual>
	</link>

	<link name="plate_castor2">
		<inertial>
			<mass value="0.01" />
			<!--<inertia ixx="4.55e-3" iyy="7.5e-3" izz="4.55e-3" ixz="0.0" ixy="0.0" iyz="0.0" />-->
			<inertia ixx="4.55e-5" izz="4.55e-5" iyy="4.55e-5" ixz="0.0" ixy="0.0" iyz="0.0" />
		</inertial>
		<collision name="castor_plate_collision2">
			<origin xyz="0 0 0" rpy="0 0 0" />
			<geometry>
				<cylinder length="0.01" radius="0.01" />
			</geometry>
		</collision>
		<visual name="castor_plate_visual2">
			<origin xyz="0 0 0" rpy="0 0 0" />
			<geometry>
				<cylinder length="0.01" radius="0.01" />
			</geometry>
		</visual>
	</link>

	<joint name="chassis_plate" type="fixed">
		<origin xyz="-0.2 0 -0.1" rpy="0 0 0" />
		<parent link="chassis" />
		<child link="plate_castor2" />
	</joint>
	<joint name="plate2_plate" type="continuous">
		<origin xyz="0 0 -0.01" rpy="0 0 0" />
		<parent link="plate_castor2" />
		<child link="plate_castor" />
		<axis xyz="0 0 1" />
		<dynamics damping="0.005" friction="0.01" />
	</joint>

	<joint name="plate_castor_joint" type="continuous">
		<origin xyz="-0.01 0 -0.01" rpy="0 0 0" />
		<parent link="plate_castor" />
		<child link="castor" />
		<axis xyz="0 1 0" />
		<dynamics damping="0.005" friction="0.01" />
	</joint>

	<!--
		<collision name="castor_collision">
			<origin xyz="-0.2 0 -0.10" rpy="0 0 0" />
			<geometry>
				<sphere radius="0.04" />
			</geometry>
			<surface>
				<friction>
					<ode>
						<mu>0</mu>
						<mu2>0</mu2>
						<slip1>0</slip1>
						<slip2>0</slip2>
					</ode>
				</friction>
			</surface>
		</collision>
		<visual name="castor_visual">
			<origin xyz="-0.20 0 -0.10" rpy="0 0 0" />
			<geometry>
				<sphere radius="0.04" />
			</geometry>
			<material name="chasis_gazebo" />
		</visual>
	</link>-->
	<xacro:include filename="$(find gazebo_ros_motors)/xacro/dc_motor.xacro" />

	<xacro:macro name="wheel" params="name pos">
		<xacro:property name="position" value="0.1 ${pos*0.17} -0.05" />
		<!--<xacro:property name="position" value="0.0 ${pos*0.17} -0.037" />-->
		<xacro:property name="position2" value="0 0 0" />
		<xacro:property name="orientation" value="1.57 0 0" />
		<xacro:property name="orientation2" value="0 0 0" />
		<link name="${name}_wheel">
			<inertial>
				<mass value="1.0" />
				<!--<inertia ixx="4.55e-3" iyy="7.5e-3" izz="4.55e-3" ixz="0.0" ixy="0.0" iyz="0.0" />-->
				<inertia ixx="3.0334e-3" izz="5.0e-3" iyy="4.55e-3" ixz="0.0" ixy="0.0" iyz="0.0" />
			</inertial>
			<collision name="${name}_collision">
				<origin xyz="${position2}" rpy="${orientation2}" />
				<geometry>
					<!--<mesh filename="package://pioneer2dx/meshes/wheel_v5.dae" />--> <!--21.6cm de diametro por 8cm de ancho perfil esferico -->
					<cylinder length="0.08" radius="0.108" />
				</geometry>
				<surface>
					<friction>
						<ode>
							<mu>0.16</mu>
							<mu2>0.16</mu2>
							<slip1>0</slip1>
							<slip2>0</slip2>
							<maxVel>0.0</maxVel>
							<minDepth>0.001</minDepth>
						</ode>
					</friction>
				</surface>
			</collision>
			<visual name="${name}_visual">
				<origin xyz="${position2}" rpy="${orientation}" />
				<geometry>
					<mesh filename="package://pioneer2dx/meshes/wheel_v5.dae" /> <!--21.6cm de diametro por 8cm de ancho perfil esferico -->
				</geometry>

			</visual>
		</link>
		<xacro:dc_motor motor_name="${name}_dc_motor" parent_link="chassis" child_link="${name}_wheel">
		<xacro:property name="params_yaml" value="$(find gazebo_ros_motors)/params/dc_motor.yaml" />
		<!--<origin xyz="0.1 ${pos*0.17} -0.037" rpy="-1.57 0 0" />-->
		<origin xyz="${position}" rpy="-1.57 0 0" />
		<axis xyz="0 0 1" />

		<!--<joint name="${name}_wheel_hinge" type="continuous">
			<origin xyz="${position}" rpy="-1.57 0 0" />
			<parent link="chassis" />
			<child link="${name}_wheel" />
			<axis xyz="0 1 0" />
			<axis xyz="0 0 1" />
			<limit effort="100" velocity="12" />
			<safety_controller k_velocity="10" />
			<limit effort="30" velocity="1" lower="-7" upper="7" />
		</joint>-->
		<!--<joint name="${name}_wheel_hinge" type="fixed">
			<origin xyz="0.1 ${pos*0.17} -0.037" rpy="-1.57 0 0" />
			<parent link="chassis" />
			<child link="${name}_wheel" />
			<axis xyz="0 0 1" />
		</joint>-->
		<!--
    <gazebo reference="${name}_wheel">
		<axis>
			    <xyz>0 1 0</xyz>
			    <limit>
				    <velocity>0.2</velocity>
				    <effort>-1</effort>
			    </limit>
		</axis>
	<physics>
	    <provide_feedback>True</provide_feedback>
	</physics>
    </gazebo>-->

		</xacro:dc_motor>-->

	</xacro:macro>
	<xacro:wheel name="right" pos="-1" />
	<xacro:wheel name="left" pos="1" />


	<xacro:macro name="Camara_config" params="name" >
		<!-- Crea una caja cuadrada con un enlace, y le pone un nombre. El pluging esta en la linea 296 para abajo -->
		<link name="Camera">
			<visual name="camera_visual">
				<origin xyz="0 0 0" rpy="0 0 0" />
				<geometry>
					<box size="0.1 0.1 0.1" />
				</geometry>
				<material name="camera_color">
					<color rgba="1 1 1 1" />
				</material>

			</visual>
		</link>
		<joint name="camera_to_chassis" type="fixed">
			<parent link="chassis" />
			<child link="Camera" />
			<origin xyz="0.14 0 0.5" rpy="0 0 0" />
			-->
			<!--<origin xyz="0.14 0 0.5" rpy="0 0 0" />-->
		</joint>

		<!-- generate an optical frame 
      http://www.ros.org/reps/rep-0103.html#suffix-frames
      so that ros and opencv can operate on the camera frame correctly 
      -->
		<joint name="camera_optical_joint" type="fixed">
			<!-- these values have to be these values otherwise the gazebo camera
        image won't be aligned properly with the frame it is supposedly
        originating from -->
			<origin xyz="0 0 0" rpy="${-pi/2} 0 ${-pi/2}" />
			<!--<parent link="camera_link"/>-->
			<parent link="Camera" />
			<child link="camera_link_optical" />
		</joint>

		<link name="camera_link_optical"></link>
	</xacro:macro>


	<xacro:macro name="lidar_link" params="name posrpy posz">

		<link name="${name}">
			<visual>
				<origin xyz="0 0 0" rpy="0 0 0" />
				<geometry>
					<mesh filename="package://pioneer2dx/meshes/hokuyo.dae" />
				</geometry>
			</visual>
		</link>
		<joint name="lidar_to_chassis_${name}" type="fixed">
			<parent link="chassis" />
			<child link="${name}" />
			<axis xyz="0 1 0" />
			<origin xyz="0.14 0 ${posz}" rpy="${posrpy}" />
		</joint>

	</xacro:macro>
	<!-- Fuente: http://gazebosim.org/tutorials?tut=ros_gzplugins -->
	<!-- Plugins -->
	<!-- camera -->

	
	<xacro:include filename="$(find pioneer2dx)/plugins/camera_stereo_plug.xacro"/>-->
	<!--<xacro:include filename="$(find pioneer2dx)/plugins/camera_stereo_plug_groundtruth.xacro"/>-->
	<xacro:Camara_config name="Camara_1"/>-->

	<xacro:include filename="$(find pioneer2dx)/plugins/lidar_plug.xacro"/>-->
	<xacro:lidar_link name="lidar_horizontal" posrpy="0 0 0" posz="0.3"/>-->
	<xacro:lidar_config name="lidar_horizontal" distance="5.0"/>-->

	<!--<xacro:lidar_link name="Lidar_vertical" posrpy="1.5 0 1.5" posz="0.4"/>
    <xacro:lidar_config name="Lidar_vertical"/>-->
	<!--<xacro:include filename="./plugins/differential_plug.xacro"/>-->
	<!--<xacro:include filename="$(find pioneer2dx)/plugins/transmition_velocity.xacro"/>-->
	<!--<xacro:include filename="$(find pioneer2dx)/plugins/transmition_effort.xacro"/>-->
	<!--<xacro:include filename="$(find pioneer2dx)/plugins/transmition_effort_manual.xacro"/>-->
	<!--  <plugin filename="libDiffDrivePlugin.so" name="diff_drive">
	      <left_joint>left_wheel_hinge</left_joint>
	      <right_joint>right_wheel_hinge</right_joint>
	      <torque>5</torque>
    </plugin> -->
</robot>