<?xml version="1.0" encoding="utf-8"?>
<!-- =================================================================================== -->
<!-- |    This document was autogenerated by xacro from model.xacro                    | -->
<!-- |    EDITING THIS FILE BY HAND IS NOT RECOMMENDED                                 | -->
<!-- =================================================================================== -->
<robot name="pioneer2dx">
  <material name="chasis_gazebo">
    <color rgba="1 0 0 1"/>
  </material>
  <material name="ruedas_gazebo">
    <color rgba="0 0 0 1"/>
  </material>
  <link name="base_link"/>
  <joint name="base_link_to_chassis" type="fixed">
    <parent link="base_link"/>
    <child link="chassis"/>
  </joint>
  <link name="chassis">
    <origin rpy="0 0 0" xyz="0 0 0.16"/>
    <inertial>
      <mass value="5.67"/>
      <inertia ixx="0.07" ixy="0" ixz="0" iyy="0.08" iyz="0" izz="0.10"/>
    </inertial>
    <collision name="collision">
      <geometry>
        <box size="0.445 0.277 0.17"/>
      </geometry>
    </collision>
    <collision name="castor_collision">
      <origin rpy="0 0 0" xyz="-0.2 0 -0.12"/>
      <geometry>
        <sphere radius="0.04"/>
      </geometry>
      <surface>
        <friction>
          <ode>
            <mu>0</mu>
            <mu2>0</mu2>
            <slip1>0</slip1>
            <slip2>0</slip2>
          </ode>
        </friction>
      </surface>
    </collision>
    <visual name="visual">
      <origin rpy="0 0 0" xyz="0 0 0.04"/>
      <geometry>
        <mesh filename="package://pioneer2dx/meshes/chassis.dae"/>
        <!--<mesh filename="file://$(arg meshlocation)/meshes/chassis.dae"/>-->
      </geometry>
    </visual>
    <visual name="castor_visual">
      <origin rpy="0 0 0" xyz="-0.20 0 -0.12"/>
      <geometry>
        <sphere radius="0.04"/>
      </geometry>
      <material name="chasis_gazebo"/>
      <!--<material>
				<script>
					<uri>file://media/materials/scripts/gazebo.material</uri>
					<name>Gazebo/FlatBlack</name>
				</script>
			</material>-->
    </visual>
  </link>
  <link name="right_wheel">
    <inertial>
      <mass value="1.5"/>
      <inertia ixx="0.0051" ixy="0" ixz="0" iyy="0.0051" iyz="0" izz="0.090"/>
    </inertial>
    <collision name="collision">
      <origin rpy="0 1.5707 1.570" xyz="0 0 0"/>
      <geometry>
        <cylinder length="0.05" radius="0.11"/>
      </geometry>
      <!--<contact_coefficients mu="100000" kp="0" kd="0"/>-->
    </collision>
    <visual name="right_visual">
      <origin rpy="0 1.5707 1.570" xyz="0 0 0"/>
      <geometry>
        <cylinder length="0.05" radius="0.11"/>
      </geometry>
      <material name="ruedas_gazebo"/>
      <!--
		<material>
			<script>
				<uri>file://media/materials/scripts/gazebo.material</uri>
				<name>Gazebo/FlatBlack</name>
			</script>
		</material>
	-->
    </visual>
  </link>
  <joint name="right_wheel_hinge" type="continuous">
    <origin rpy="0 0 0" xyz="0.1 0.17 -0.037"/>
    <parent link="chassis"/>
    <child link="right_wheel"/>
    <axis xyz="0 1 0"/>
    <!-- <limit effort="30" velocity="1" lower="-7" upper="7" />-->
  </joint>
  <gazebo reference="right_wheel">
    <mu1 value="0.01"/>
    <mu2 value="0.01"/>
  </gazebo>
  <link name="left_wheel">
    <inertial>
      <mass value="1.5"/>
      <inertia ixx="0.0051" ixy="0" ixz="0" iyy="0.0051" iyz="0" izz="0.090"/>
    </inertial>
    <collision name="collision">
      <origin rpy="0 1.5707 1.570" xyz="0 0 0"/>
      <geometry>
        <cylinder length="0.05" radius="0.11"/>
      </geometry>
      <!--<contact_coefficients mu="100000" kp="0" kd="0"/>-->
    </collision>
    <visual name="left_visual">
      <origin rpy="0 1.5707 1.570" xyz="0 0 0"/>
      <geometry>
        <cylinder length="0.05" radius="0.11"/>
      </geometry>
      <material name="ruedas_gazebo"/>
      <!--
		<material>
			<script>
				<uri>file://media/materials/scripts/gazebo.material</uri>
				<name>Gazebo/FlatBlack</name>
			</script>
		</material>
	-->
    </visual>
  </link>
  <joint name="left_wheel_hinge" type="continuous">
    <origin rpy="0 0 0" xyz="0.1 -0.17 -0.037"/>
    <parent link="chassis"/>
    <child link="left_wheel"/>
    <axis xyz="0 1 0"/>
    <!-- <limit effort="30" velocity="1" lower="-7" upper="7" />-->
  </joint>
  <gazebo reference="left_wheel">
    <mu1 value="0.01"/>
    <mu2 value="0.01"/>
  </gazebo>
  <link name="Camera">
    <visual name="camera_visual">
      <origin rpy="0 0 0" xyz="0 0 0"/>
      <geometry>
        <box size="0.1 0.1 0.1"/>
      </geometry>
      <material name="camera_color">
        <color rgba="1 1 1 1"/>
      </material>
    </visual>
  </link>
  <joint name="camera_to_chassis" type="fixed">
    <parent link="chassis"/>
    <child link="Camera"/>
    <origin rpy="0 0 0" xyz="0.14 0 0.16"/>
  </joint>
  <!-- Fuente: http://gazebosim.org/tutorials?tut=ros_gzplugins -->
  <!-- Plugins -->
  <!-- camera -->
  <gazebo reference="Camera">
    <sensor name="camera1" type="camera">
      <update_rate>15.0</update_rate>
      <camera name="head">
        <horizontal_fov>1.3962634</horizontal_fov>
        <image>
          <width>800</width>
          <height>600</height>
          <format>R8G8B8</format>
        </image>
        <clip>
          <near>0.02</near>
          <far>300</far>
        </clip>
        <noise>
          <type>gaussian</type>
          <!-- Noise is sampled independently per pixel on each frame.
               That pixel's noise value is added to each of its color
               channels, which at that point lie in the range [0,1]. -->
          <mean>0.0</mean>
          <stddev>0.007</stddev>
        </noise>
      </camera>
      <plugin filename="libgazebo_ros_camera.so" name="camera_controller">
        <alwaysOn>true</alwaysOn>
        <updateRate>0.0</updateRate>
        <cameraName>pioneer2dx/camera1</cameraName>
        <imageTopicName>image_raw</imageTopicName>
        <cameraInfoTopicName>camera_info</cameraInfoTopicName>
        <frameName>camera_link</frameName>
        <hackBaseline>0.07</hackBaseline>
        <distortionK1>0.0</distortionK1>
        <distortionK2>0.0</distortionK2>
        <distortionK3>0.0</distortionK3>
        <distortionT1>0.0</distortionT1>
        <distortionT2>0.0</distortionT2>
      </plugin>
    </sensor>
  </gazebo>
  <!--<xacro:include filename="./plugins/camera_plug.xacro"/>
    <xacro:include filename="./plugins/lidar_plug.xacro"/>-->
  <link name="Lidar_horizontal">
    <visual>
      <origin rpy="0 0 0" xyz="0 0 0"/>
      <geometry>
        <mesh filename="package://pioneer2dx/meshes/hokuyo.dae"/>
        <!--<mesh filename="file://$(arg meshlocation)/meshes/hokuyo.dae"/>-->
      </geometry>
    </visual>
  </link>
  <joint name="lidar_to_chassis_Lidar_horizontal" type="fixed">
    <parent link="chassis"/>
    <child link="Lidar_horizontal"/>
    <axis xyz="0 1 0"/>
    <origin rpy="0 0 0" xyz="0.14 0 0.3"/>
  </joint>
  <gazebo reference="Lidar_horizontal">
    <!--<sensor type="gpu_ray" name="head_hokuyo_sensor">-->
    <!-- activar gpu support-->
    <sensor name="head_hokuyo_sensor" type="ray">
      <pose>0 0 0 0 0 0</pose>
      <visualize>false</visualize>
      <update_rate>25</update_rate>
      <ray>
        <scan>
          <horizontal>
            <samples>720</samples>
            <resolution>1</resolution>
            <min_angle>-1.570796</min_angle>
            <max_angle>1.570796</max_angle>
          </horizontal>
        </scan>
        <range>
          <min>0.50</min>
          <max>20.0</max>
          <resolution>0.03</resolution>
        </range>
        <noise>
          <type>gaussian</type>
          <!-- noise parameters based on published spec for hokuyo laser
               achieving "+-30mm" accuracy at range < 10m.  a mean of 0.0m and
               stddev of 0.01m will put 99.7% of samples within 0.03m of the true
               reading. -->
          <mean>0.0</mean>
          <stddev>0.012</stddev>
        </noise>
      </ray>
      <!--<plugin name="gazebo_ros_head_hokuyo_controller" filename="libgazebo_ros_gpu_laser.so">-->
      <!-- activar gpu support-->
      <plugin filename="libgazebo_ros_laser.so" name="gazebo_ros_head_hokuyo_controller">
        <topicName>pioneer2dx/laser/scan_Lidar_horizontal</topicName>
        <frameName>Lidar_horizontal</frameName>
        <robotNamespace>/</robotNamespace>
      </plugin>
    </sensor>
  </gazebo>
  <transmission name="left_wheel_transmission">
    <type>transmission_interface/SimpleTransmission</type>
    <joint name="left_wheel_hinge">
      <hardwareInterface>hardware_interface/VelocityJointInterface</hardwareInterface>
    </joint>
    <actuator name="motor_left">
      <mechanicalReduction>1</mechanicalReduction>
      <hardwareInterface>VelocityJointInterface</hardwareInterface>
    </actuator>
  </transmission>
  <transmission name="right_wheel_transmission">
    <type>transmission_interface/SimpleTransmission</type>
    <joint name="right_wheel_hinge">
      <hardwareInterface>hardware_interface/VelocityJointInterface</hardwareInterface>
    </joint>
    <actuator name="motor_right">
      <mechanicalReduction>1</mechanicalReduction>
      <hardwareInterface>VelocityJointInterface</hardwareInterface>
    </actuator>
  </transmission>
  <gazebo>
    <plugin filename="libgazebo_ros_control.so" name="gazebo_ros_control">
      <robotNamespace>/rrbot</robotNamespace>
    </plugin>
  </gazebo>
  <plugin filename="libDiffDrivePlugin.so" name="diff_drive">
    <left_joint>left_wheel_hinge</left_joint>
    <right_joint>right_wheel_hinge</right_joint>
    <torque>5</torque>
  </plugin>
</robot>

