<sdf version='1.7'>
  <model name='pioneer2dx'>
    <link name='base_link'>
      <inertial>
        <pose>-0.083514 0 -0.006245 0 -0 0</pose>
        <mass>12.01</mass>
        <inertia>
          <ixx>0.154282</ixx>
          <ixy>0</ixy>
          <ixz>0.00596353</ixz>
          <iyy>0.226051</iyy>
          <iyz>7.16694e-07</iyz>
          <izz>0.320581</izz>
        </inertia>
      </inertial>
      <collision name='base_link_fixed_joint_lump__chasis_collision_collision'>
        <pose>-0.1 0 0 0 -0 0</pose>
        <geometry>
          <box>
            <size>0.445 0.277 0.17</size>
          </box>
        </geometry>
      </collision>
      <collision name='base_link_fixed_joint_lump__castor_plate_collision2_collision_1'>
        <pose>-0.3 0 -0.1 0 -0 0</pose>
        <geometry>
          <cylinder>
            <length>0.01</length>
            <radius>0.01</radius>
          </cylinder>
        </geometry>
      </collision>
      <collision name='base_link_fixed_joint_lump__left_collision_collision_2'>
        <pose>0 0.17 -0.037 0 -0 0</pose>
        <geometry>
          <mesh>
            <scale>1 1 1</scale>
            <uri>model://pioneer2dx/meshes/wheel_v5.dae</uri>
          </mesh>
        </geometry>
        <surface>
          <friction>
            <ode>
              <mu>0.2</mu>
              <mu2>0.2</mu2>
              <slip1>0</slip1>
              <slip2>0</slip2>
              <maxVel>0.0</maxVel>
              <minDepth>0.001</minDepth>
            </ode>
          </friction>
        </surface>
      </collision>
      <collision name='base_link_fixed_joint_lump__right_collision_collision_3'>
        <pose>0 -0.17 -0.037 0 -0 0</pose>
        <geometry>
          <mesh>
            <scale>1 1 1</scale>
            <uri>model://pioneer2dx/meshes/wheel_v5.dae</uri>
          </mesh>
        </geometry>
        <surface>
          <friction>
            <ode>
              <mu>0.2</mu>
              <mu2>0.2</mu2>
              <slip1>0</slip1>
              <slip2>0</slip2>
              <maxVel>0.0</maxVel>
              <minDepth>0.001</minDepth>
            </ode>
          </friction>
        </surface>
      </collision>
      <visual name='base_link_fixed_joint_lump__chasis_visual_visual'>
        <pose>-0.1 0 0.04 0 -0 0</pose>
        <geometry>
          <mesh>
            <scale>1 1 1</scale>
            <uri>model://pioneer2dx/meshes/chassis.dae</uri>
          </mesh>
        </geometry>
      </visual>
      <visual name='base_link_fixed_joint_lump__castor_plate_visual2_visual_1'>
        <pose>-0.3 0 -0.1 0 -0 0</pose>
        <geometry>
          <cylinder>
            <length>0.01</length>
            <radius>0.01</radius>
          </cylinder>
        </geometry>
      </visual>
      <visual name='base_link_fixed_joint_lump__left_visual_visual_2'>
        <pose>0 0.17 -0.037 0 -0 0</pose>
        <geometry>
          <mesh>
            <scale>1 1 1</scale>
            <uri>model://pioneer2dx/meshes/wheel_v5.dae</uri>
          </mesh>
        </geometry>
      </visual>
      <visual name='base_link_fixed_joint_lump__right_visual_visual_3'>
        <pose>0 -0.17 -0.037 0 -0 0</pose>
        <geometry>
          <mesh>
            <scale>1 1 1</scale>
            <uri>model://pioneer2dx/meshes/wheel_v5.dae</uri>
          </mesh>
        </geometry>
      </visual>
    </link>
    <joint name='plate2_plate' type='revolute'>
      <pose relative_to='base_link'>-0.3 0 -0.11 0 -0 0</pose>
      <parent>base_link</parent>
      <child>plate_castor</child>
      <axis>
        <xyz>0 0 1</xyz>
        <limit>
          <lower>-1e+16</lower>
          <upper>1e+16</upper>
        </limit>
        <dynamics>
          <damping>0.005</damping>
          <friction>0.01</friction>
          <spring_reference>0</spring_reference>
          <spring_stiffness>0</spring_stiffness>
        </dynamics>
      </axis>
    </joint>
    <link name='plate_castor'>
      <pose relative_to='plate2_plate'>0 0 0 0 -0 0</pose>
      <inertial>
        <pose>0 0 0 0 -0 0</pose>
        <mass>0.01</mass>
        <inertia>
          <ixx>4.55e-05</ixx>
          <ixy>0</ixy>
          <ixz>0</ixz>
          <iyy>4.55e-05</iyy>
          <iyz>0</iyz>
          <izz>4.55e-05</izz>
        </inertia>
      </inertial>
      <collision name='plate_castor_fixed_joint_lump__castor_plate_collision_collision'>
        <pose>0 0 0 0 -0 0</pose>
        <geometry>
          <cylinder>
            <length>0.01</length>
            <radius>0.01</radius>
          </cylinder>
        </geometry>
      </collision>
      <visual name='plate_castor_fixed_joint_lump__castor_plate_visual_visual'>
        <pose>0 0 0 0 -0 0</pose>
        <geometry>
          <cylinder>
            <length>0.01</length>
            <radius>0.01</radius>
          </cylinder>
        </geometry>
      </visual>
    </link>
    <joint name='plate_castor_joint' type='revolute'>
      <pose relative_to='plate_castor'>-0.1 0 -0.016 0 -0 0</pose>
      <parent>plate_castor</parent>
      <child>castor</child>
      <axis>
        <xyz>0 1 0</xyz>
        <limit>
          <lower>-1e+16</lower>
          <upper>1e+16</upper>
        </limit>
        <dynamics>
          <damping>0.005</damping>
          <friction>0.01</friction>
          <spring_reference>0</spring_reference>
          <spring_stiffness>0</spring_stiffness>
        </dynamics>
      </axis>
    </joint>
    <link name='castor'>
      <pose relative_to='plate_castor_joint'>0 0 0 0 -0 0</pose>
      <inertial>
        <pose>0 0 0 0 -0 0</pose>
        <mass>0.15</mass>
        <inertia>
          <ixx>0.000455</ixx>
          <ixy>0</ixy>
          <ixz>0</ixz>
          <iyy>0.00075</iyy>
          <iyz>0</iyz>
          <izz>0.000455</izz>
        </inertia>
      </inertial>
      <collision name='castor_collision_collision'>
        <pose>0 0 0 0 -0 0</pose>
        <geometry>
          <mesh>
            <scale>0.3 0.3 0.3</scale>
            <uri>model://pioneer2dx/meshes/wheel_v5.dae</uri>
          </mesh>
        </geometry>
        <surface>
          <friction>
            <ode>
              <mu>0.0</mu>
              <mu2>0.0</mu2>
              <slip1>0</slip1>
              <slip2>0</slip2>
              <maxVel>0.0</maxVel>
              <minDepth>0.001</minDepth>
            </ode>
          </friction>
        </surface>
      </collision>
      <visual name='castor_visual_visual'>
        <pose>0 0 0 0 -0 0</pose>
        <geometry>
          <mesh>
            <scale>0.3 0.3 0.3</scale>
            <uri>model://pioneer2dx/meshes/wheel_v5.dae</uri>
          </mesh>
        </geometry>
      </visual>
    </link>
  </model>
</sdf>
